Workbook

Sheet Sobre
A1: Análise de Gestão de Ativos de TI - Excel, Power Query e Tabelas Dinâmicas
A3: Todos os dados desta planilha são SINTÉTICOS (simulados). Não vêm de nenhuma organização real e não representam nenhuma organização real.
A5: Abas
A6: Indicadores - indicadores principais e tabelas-resumo, todos calculados por fórmulas sobre as abas de dados.
A7: Ativos - 5.000 ativos de informática simulados (físicos + máquinas virtuais). Tabela do Excel: tbl_Ativos.
A8: Locais - 12 unidades simuladas. Tabela do Excel: tbl_Locais.
A9: Movimentações - despachos, devoluções, transferências e retiradas do pool. Tabela do Excel: tbl_Movimentacoes.
A10: Incidentes - incidentes de suporte com gravidade e tempo de resolução. Tabela do Excel: tbl_Incidentes.
A12: Como usar
A13: 1. Altere as células amarelas da aba Indicadores (data de referência e limites de ciclo de vida); todos os indicadores se recalculam.
A14: 2. Crie Tabelas Dinâmicas a partir das tabelas acima (veja docs/guia-tabelas-dinamicas.md).
A15: 3. Para reproduzir a limpeza no Power Query, carregue os CSVs brutos de /data/raw com os scripts M de /power-query.
... A21: Remover espaços extras, padronizar o status em Title Case, remover 25 linhas duplicadas por id_ativo e substituir departamento em branco por 'Não atribuído'.

Sheet Indicadores
A1: Gestão de Ativos de TI - Resumo de Indicadores (dados sintéticos)
A3: Entradas (altere as células amarelas)
A4: Data de referência | B4: 46313 | C4: Data usada para calcular a idade dos ativos e o status da garantia. Use a data de extração dos dados.
A5: Limite de envelhecimento (anos) | B5: 3 | C5: Premissa: ativos com 3 anos ou mais são 'Envelhecendo'. Ciclos de renovação típicos: 3 a 5 anos.
A6: Limite de fim de vida (anos) | B6: 5 | C6: Premissa: ativos com 5 anos ou mais estão em 'Fim de Vida' e são candidatos à substituição.
A8: Indicadores principais
A9: Indicador | B9: Valor | C9: Definição
A10: Total de ativos | B10: =COUNTA(Ativos!$A$2:$A$5001) -> 5000 | C10: Todos os registros de ativos após a limpeza (físicos + virtuais).
A11: Ativos ativos (exceto Baixados) | B11: =COUNTA(Ativos!$A$2:$A$5001)-COUNTIF(Ativos!$G$2:$G$5001,"Baixado") -> 4601 | C11: Total menos os Baixados.
A12: Em Uso | B12: =COUNTIF(Ativos!$G$2:$G$5001,"Em Uso") -> 3420 | C12: Atribuídos a um usuário ou departamento.
A13: Em Estoque | B13: =COUNTIF(Ativos!$G$2:$G$5001,"Em Estoque") -> 522 | C13: Disponíveis em estoque, fora do pool.
A14: Em Manutenção | B14: =COUNTIF(Ativos!$G$2:$G$5001,"Em Manutenção") -> 151 | C14: Atualmente em manutenção.
A15: Baixados | B15: =COUNTIF(Ativos!$G$2:$G$5001,"Baixado") -> 399 | C15: Desativados (baixa patrimonial).
A16: Ativos do pool (físicos + virtuais) | B16: =COUNTIF(Ativos!$J$2:$J$5001,"S") -> 508 | C16: Máquinas gerenciadas no pool compartilhado.
A17: Utilização do pool | B17: =IF(B16=0,0,COUNTIF(Ativos!$G$2:$G$5001,"Pool - Emprestado")/B16) -> 0.44291339 | C17: Ativos do pool emprestados / total de ativos do pool.
A18: Idade média dos ativos físicos ativos (anos) | B18: =AVERAGEIFS(Ativos!$L$2:$L$5001,Ativos!$G$2:$G$5001,"<>Baixado") -> 3.9774597 | C18: Máquinas virtuais ficam de fora (sem data de compra).
A19: % dos ativos físicos ativos em Fim de Vida | B19: =COUNTIFS(Ativos!$M$2:$M$5001,"Fim de Vida",Ativos!$G$2:$G$5001,"<>Baixado")/COUNTIFS(Ativos!$M$2:$M$5001,"<>Virtual",Ativos!$G$2:$G$5001,"<>Baixado") -> 0.30561236 | C19: Idade >= limite de fim de vida.
A20: % dos ativos físicos ativos fora da garantia | B20: =COUNTIFS(Ativos!$N$2:$N$5001,"Vencida",Ativos!$G$2:$G$5001,"<>Baixado")/COUNTIFS(Ativos!$N$2:$N$5001,"<>N/A",Ativos!$G$2:$G$5001,"<>Baixado") -> 0.599182 | C20: Data de fim da garantia anterior à data de referência.
A21: Incidentes nos últimos 12 meses | B21: =COUNTIFS(Incidentes!$F$2:$F$9001,">"&EDATE($B$4,-12),Incidentes!$F$2:$F$9001,"<="&$B$4) -> 5771 | C21: Abertos nos 12 meses anteriores à data de referência.
A22: Incidentes por 100 ativos ativos (12 meses) | B22: =IF(B11=0,0,B21/B11*100) -> 125.42925 | C22: Taxa de incidentes normalizada pelo tamanho do parque.
A23: Tempo médio de resolução (horas) | B23: =AVERAGE(Incidentes!$H$2:$H$9001) -> 14.502733 | C23: Média de horas_resolucao em todos os incidentes.
A25: Por local
A26: Local | B26: Ativos ativos | C26: Idade média (anos) | D26: Fim de Vida | E26: Ativos do pool | F26: Incidentes (12m) | G26: Incidentes por 100 ativos
A27: =Locais!B2 -> Sede - Brasília | B27: =COUNTIFS(Ativos!$H$2:$H$5001,Locais!$A2,Ativos!$G$2:$G$5001,"<>Baixado") -> 1100 | C27: =IFERROR(AVERAGEIFS(Ativos!$L$2:$L$5001,Ativos!$H$2:$H$5001,Locais!$A2,Ativos!$G$2:$G$5001,"<>Baixado"),0) -> 4.0398889 | D27: =COUNTIFS(Ativos!$H$2:$H$5001,Locais!$A2,Ativos!$M$2:$M$5001,"Fim de Vida",Ativos!$G$2:$G$5001,"<>Baixado") -> 287 | E27: =COUNTIFS(Ativos!$H$2:$H$5001,Locais!$A2,Ativos!$J$2:$J$5001,"S") -> 260 | F27: =COUNTIFS(Incidentes!$C$2:$C$9001,Locais!$A2,Incidentes!$F$2:$F$9001,">"&EDATE($B$4,-12),Incidentes!$F$2:$F$9001,"<="&$B$4) -> 1338 | G27: =IF(B27=0,0,F27/B27*100) -> 121.63636
A28: =Locais!B3 -> Regional - São Paulo | B28: =COUNTIFS(Ativos!$H$2:$H$5001,Locais!$A3,Ativos!$G$2:$G$5001,"<>Baixado") -> 772 | C28: =IFERROR(AVERAGEIFS(Ativos!$L$2:$L$5001,Ativos!$H$2:$H$5001,Locais!$A3,Ativos!$G$2:$G$5001,"<>Baixado"),0) -> 4.0138601 | D28: =COUNTIFS(Ativos!$H$2:$H$5001,Locais!$A3,Ativos!$M$2:$M$5001,"Fim de Vida",Ativos!$G$2:$G$5001,"<>Baixado") -> 228 | E28: =COUNTIFS(Ativos!$H$2:$H$5001,Locais!$A3,Ativos!$J$2:$J$5001,"S") -> 59 | F28: =COUNTIFS(Incidentes!$C$2:$C$9001,Locais!$A3,Incidentes!$F$2:$F$9001,">"&EDATE($B$4,-12),Incidentes!$F$2:$F$9001,"<="&$B$4) -> 993 | G28: =IF(B28=0,0,F28/B28*100) -> 128.62694
A29: =Locais!B4 -> Regional - Rio de Janeiro | B29: =COUNTIFS(Ativos!$H$2:$H$5001,Locais!$A4,Ativos!$G$2:$G$5001,"<>Baixado") -> 522 | C29: =IFERROR(AVERAGEIFS(Ativos!$L$2:$L$5001,Ativos!$H$2:$H$5001,Locais!$A4,Ativos!$G$2:$G$5001,"<>Baixado"),0) -> 3.9429119 | D29: =COUNTIFS(Ativos!$H$2:$H$5001,Locais!$A4,Ativos!$M$2:$M$5001,"Fim de Vida",Ativos!$G$2:$G$5001,"<>Baixado") -> 147 | E29: =COUNTIFS(Ativos!$H$2:$H$5001,Locais!$A4,Ativos!$J$2:$J$5001,"S") -> 29 | F29: =COUNTIFS(Incidentes!$C$2:$C$9001,Locais!$A4,Incidentes!$F$2:$F$9001,">"&EDATE($B$4,-12),Incidentes!$F$2:$F$9001,"<="&$B$4) -> 657 | G29: =IF(B29=0,0,F29/B29*100) -> 125.86207
A30: =Locais!B5 -> Regional - Belo Horizonte | B30: =COUNTIFS(Ativos!$H$2:$H$5001,Locais!$A5,Ativos!$G$2:$G$5001,"<>Baixado") -> 294 | C30: =IFERROR(AVERAGEIFS(Ativos!$L$2:$L$5001,Ativos!$H$2:$H$5001,Locais!$A5,Ativos!$G$2:$G$5001,"<>Baixado"),0) -> 3.9435374 | D30: =COUNTIFS(Ativos!$H$2:$H$5001,Locais!$A5,Ativos!$M$2:$M$5001,"Fim de Vida",Ativos!$G$2:$G$5001,"<>Baixado") -> 91 | E30: =COUNTIFS(Ativos!$H$2:$H$5001,Locais!$A5,Ativos!$J$2:$J$5001,"S") -> 16 | F30: =COUNTIFS(Incidentes!$C$2:$C$9001,Locais!$A5,Incidentes!$F$2:$F$9001,">"&EDATE($B$4,-12),Incidentes!$F$2:$F$9001,"<="&$B$4) -> 330 | G30: =IF(B30=0,0,F30/B30*100) -> 112.2449
A31: =Locais!B6 -> Regional - Porto Alegre | B31: =COUNTIFS(Ativos!$H$2:$H$5001,Locais!$A6,Ativos!$G$2:$G$5001,"<>Baixado") -> 280 | C31: =IFERROR(AVERAGEIFS(Ativos!$L$2:$L$5001,Ativos!$H$2:$H$5001,Locais!$A6,Ativos!$G$2:$G$5001,"<>Baixado"),0) -> 4.1096429 | D31: =COUNTIFS(Ativos!$H$2:$H$5001,Locais!$A6,Ativos!$M$2:$M$5001,"Fim de Vida",Ativos!$G$2:$G$5001,"<>Baixado") -> 98 | E31: =COUNTIFS(Ativos!$H$2:$H$5001,Locais!$A6,Ativos!$J$2:$J$5001,"S") -> 24 | F31: =COUNTIFS(Incidentes!$C$2:$C$9001,Locais!$A6,Incidentes!$F$2:$F$9001,">"&EDATE($B$4,-12),Incidentes!$F$2:$F$9001,"<="&$B$4) -> 357 | G31: =IF(B31=0,0,F31/B31*100) -> 127.5
A32: =Locais!B7 -> Regional - Curitiba | B32: =COUNTIFS(Ativos!$H$2:$H$5001,Locais!$A7,Ativos!$G$2:$G$5001,"<>Baixado") -> 253 | C32: =IFERROR(AVERAGEIFS(Ativos!$L$2:$L$5001,Ativos!$H$2:$H$5001,Locais!$A7,Ativos!$G$2:$G$5001,"<>Baixado"),0) -> 3.6391304 | D32: =COUNTIFS(Ativos!$H$2:$H$5001,Locais!$A7,Ativos!$M$2:$M$5001,"Fim de Vida",Ativos!$G$2:$G$5001,"<>Baixado") -> 61 | E32: =COUNTIFS(Ativos!$H$2:$H$5001,Locais!$A7,Ativos!$J$2:$J$5001,"S") -> 19 | F32: =COUNTIFS(Incidentes!$C$2:$C$9001,Locais!$A7,Incidentes!$F$2:$F$9001,">"&EDATE($B$4,-12),Incidentes!$F$2:$F$9001,"<="&$B$4) -> 333 | G32: =IF(B32=0,0,F32/B32*100) -> 131.62055
A33: =Locais!B8 -> Regional - Salvador | B33: =COUNTIFS(Ativos!$H$2:$H$5001,Locais!$A8,Ativos!$G$2:$G$5001,"<>Baixado") -> 321 | C33: =IFERROR(AVERAGEIFS(Ativos!$L$2:$L$5001,Ativos!$H$2:$H$5001,Locais!$A8,Ativos!$G$2:$G$5001,"<>Baixado"),0) -> 4.011215 | D33: =COUNTIFS(Ativos!$H$2:$H$5001,Locais!$A8,Ativos!$M$2:$M$5001,"Fim de Vida",Ativos!$G$2:$G$5001,"<>Baixado") -> 106 | E33: =COUNTIFS(Ativos!$H$2:$H$5001,Locais!$A8,Ativos!$J$2:$J$5001,"S") -> 26 | F33: =COUNTIFS(Incidentes!$C$2:$C$9001,Locais!$A8,Incidentes!$F$2:$F$9001,">"&EDATE($B$4,-12),Incidentes!$F$2:$F$9001,"<="&$B$4) -> 394 | G33: =IF(B33=0,0,F33/B33*100) -> 122.74143
A34: =Locais!B9 -> Regional - Recife | B34: =COUNTIFS(Ativos!$H$2:$H$5001,Locais!$A9,Ativos!$G$2:$G$5001,"<>Baixado") -> 277 | C34: =IFERROR(AVERAGEIFS(Ativos!$L$2:$L$5001,Ativos!$H$2:$H$5001,Locais!$A9,Ativos!$G$2:$G$5001,"<>Baixado"),0) -> 3.7454874 | D34: =COUNTIFS(Ativos!$H$2:$H$5001,Locais!$A9,Ativos!$M$2:$M$5001,"Fim de Vida",Ativos!$G$2:$G$5001,"<>Baixado") -> 75 | E34: =COUNTIFS(Ativos!$H$2:$H$5001,Locais!$A9,Ativos!$J$2:$J$5001,"S") -> 18 | F34: =COUNTIFS(Incidentes!$C$2:$C$9001,Locais!$A9,Incidentes!$F$2:$F$9001,">"&EDATE($B$4,-12),Incidentes!$F$2:$F$9001,"<="&$B$4) -> 331 | G34: =IF(B34=0,0,F34/B34*100) -> 119.49458
A35: =Locais!B10 -> Regional - Fortaleza | B35: =COUNTIFS(Ativos!$H$2:$H$5001,Locais!$A10,Ativos!$G$2:$G$5001,"<>Baixado") -> 233 | C35: =IFERROR(AVERAGEIFS(Ativos!$L$2:$L$5001,Ativos!$H$2:$H$5001,Locais!$A10,Ativos!$G$2:$G$5001,"<>Baixado"),0) -> 4.1854077 | D35: =COUNTIFS(Ativos!$H$2:$H$5001,Locais!$A10,Ativos!$M$2:$M$5001,"Fim de Vida",Ativos!$G$2:$G$5001,"<>Baixado") -> 84 | E35: =COUNTIFS(Ativos!$H$2:$H$5001,Locais!$A10,Ativos!$J$2:$J$5001,"S") -> 18 | F35: =COUNTIFS(Incidentes!$C$2:$C$9001,Locais!$A10,Incidentes!$F$2:$F$9001,">"&EDATE($B$4,-12),Incidentes!$F$2:$F$9001,"<="&$B$4) -> 321 | G35: =IF(B35=0,0,F35/B35*100) -> 137.76824
A36: =Locais!B11 -> Regional - Belém | B36: =COUNTIFS(Ativos!$H$2:$H$5001,Locais!$A11,Ativos!$G$2:$G$5001,"<>Baixado") -> 220 | C36: =IFERROR(AVERAGEIFS(Ativos!$L$2:$L$5001,Ativos!$H$2:$H$5001,Locais!$A11,Ativos!$G$2:$G$5001,"<>Baixado"),0) -> 3.9090909 | D36: =COUNTIFS(Ativos!$H$2:$H$5001,Locais!$A11,Ativos!$M$2:$M$5001,"Fim de Vida",Ativos!$G$2:$G$5001,"<>Baixado") -> 64 | E36: =COUNTIFS(Ativos!$H$2:$H$5001,Locais!$A11,Ativos!$J$2:$J$5001,"S") -> 18 | F36: =COUNTIFS(Incidentes!$C$2:$C$9001,Locais!$A11,Incidentes!$F$2:$F$9001,">"&EDATE($B$4,-12),Incidentes!$F$2:$F$9001,"<="&$B$4) -> 284 | G36: =IF(B36=0,0,F36/B36*100) -> 129.09091
A37: =Locais!B12 -> Regional - Manaus | B37: =COUNTIFS(Ativos!$H$2:$H$5001,Locais!$A12,Ativos!$G$2:$G$5001,"<>Baixado") -> 163 | C37: =IFERROR(AVERAGEIFS(Ativos!$L$2:$L$5001,Ativos!$H$2:$H$5001,Locais!$A12,Ativos!$G$2:$G$5001,"<>Baixado"),0) -> 4.0153374 | D37: =COUNTIFS(Ativos!$H$2:$H$5001,Locais!$A12,Ativos!$M$2:$M$5001,"Fim de Vida",Ativos!$G$2:$G$5001,"<>Baixado") -> 47 | E37: =COUNTIFS(Ativos!$H$2:$H$5001,Locais!$A12,Ativos!$J$2:$J$5001,"S") -> 9 | F37: =COUNTIFS(Incidentes!$C$2:$C$9001,Locais!$A12,Incidentes!$F$2:$F$9001,">"&EDATE($B$4,-12),Incidentes!$F$2:$F$9001,"<="&$B$4) -> 204 | G37: =IF(B37=0,0,F37/B37*100) -> 125.15337
A38: =Locais!B13 -> Regional - Goiânia | B38: =COUNTIFS(Ativos!$H$2:$H$5001,Locais!$A13,Ativos!$G$2:$G$5001,"<>Baixado") -> 166 | C38: =IFERROR(AVERAGEIFS(Ativos!$L$2:$L$5001,Ativos!$H$2:$H$5001,Locais!$A13,Ativos!$G$2:$G$5001,"<>Baixado"),0) -> 4.0144578 | D38: =COUNTIFS(Ativos!$H$2:$H$5001,Locais!$A13,Ativos!$M$2:$M$5001,"Fim de Vida",Ativos!$G$2:$G$5001,"<>Baixado") -> 57 | E38: =COUNTIFS(Ativos!$H$2:$H$5001,Locais!$A13,Ativos!$J$2:$J$5001,"S") -> 12 | F38: =COUNTIFS(Incidentes!$C$2:$C$9001,Locais!$A13,Incidentes!$F$2:$F$9001,">"&EDATE($B$4,-12),Incidentes!$F$2:$F$9001,"<="&$B$4) -> 229 | G38: =IF(B38=0,0,F38/B38*100) -> 137.95181
A39: Total | B39: =SUM(B27:B38) -> 4601 | C39: =B18 -> 3.9774597 | D39: =SUM(D27:D38) -> 1345 | E39: =SUM(E27:E38) -> 508 | F39: =SUM(F27:F38) -> 5771 | G39: =IF(B39=0,0,F39/B39*100) -> 125.42925
A41: Por tipo de ativo (ativos ativos)
A42: Tipo de ativo | B42: Ativos ativos | C42: Idade média (anos) | D42: Fim de Vida | E42: % Fim de Vida
A43: Desktop | B43: =COUNTIFS(Ativos!$B$2:$B$5001,$A43,Ativos!$G$2:$G$5001,"<>Baixado") -> 1973 | C43: =IFERROR(AVERAGEIFS(Ativos!$L$2:$L$5001,Ativos!$B$2:$B$5001,$A43,Ativos!$G$2:$G$5001,"<>Baixado"),0) -> 3.9868221 | D43: =COUNTIFS(Ativos!$B$2:$B$5001,$A43,Ativos!$M$2:$M$5001,"Fim de Vida",Ativos!$G$2:$G$5001,"<>Baixado") -> 608 | E43: =IF(B43=0,0,D43/B43) -> 0.30816016
A44: Notebook | B44: =COUNTIFS(Ativos!$B$2:$B$5001,$A44,Ativos!$G$2:$G$5001,"<>Baixado") -> 1704 | C44: =IFERROR(AVERAGEIFS(Ativos!$L$2:$L$5001,Ativos!$B$2:$B$5001,$A44,Ativos!$G$2:$G$5001,"<>Baixado"),0) -> 3.9595657 | D44: =COUNTIFS(Ativos!$B$2:$B$5001,$A44,Ativos!$M$2:$M$5001,"Fim de Vida",Ativos!$G$2:$G$5001,"<>Baixado") -> 502 | E44: =IF(B44=0,0,D44/B44) -> 0.29460094
...

Sheet Ativos
A1: id_ativo | B1: tipo_ativo | C1: fabricante | D1: modelo | E1: data_compra | F1: fim_garantia | G1: status | H1: id_local | I1: departamento | J1: pertence_pool | K1: custo_aquisicao_brl | L1: idade_anos | M1: estagio_ciclo_vida | N1: status_garantia | O1: nome_local | P1: regiao
A2: ATV-00001 | B2: Notebook | C2: Dell | D2: Latitude 5420 | E2: 44066 | F2: 45161 | G2: Em Uso | H2: LOC-01 | I2: Auditoria | J2: N | K2: 10520.53 | L2: =IF(E2="","",ROUND((Indicadores!$B$4-E2)/365.25,1)) -> 6.2 | M2: =IF(E2="","Virtual",IF(L2>=Indicadores!$B$6,"Fim de Vida",IF(L2>=Indicadores!$B$5,"Envelhecendo","Atual"))) -> Fim de Vida | N2: =IF(F2="","N/A",IF(F2<Indicadores!$B$4,"Vencida","Vigente")) -> Vencida | O2: =INDEX(Locais!$B$2:$B$13,MATCH(H2,Locais!$A$2:$A$13,0)) -> Sede - Brasília | P2: =INDEX(Locais!$C$2:$C$13,MATCH(H2,Locais!$A$2:$A$13,0)) -> Centro-Oeste
A3: ATV-00002 | B3: Desktop | C3: Lenovo | D3: ThinkCentre M70q | E3: 45897 | F3: 46992 | G3: Em Uso | H3: LOC-09 | I3: Não atribuído | J3: N | K3: 4803.91 | L3: =IF(E3="","",ROUND((Indicadores!$B$4-E3)/365.25,1)) -> 1.1 | M3: =IF(E3="","Virtual",IF(L3>=Indicadores!$B$6,"Fim de Vida",IF(L3>=Indicadores!$B$5,"Envelhecendo","Atual"))) -> Atual | N3: =IF(F3="","N/A",IF(F3<Indicadores!$B$4,"Vencida","Vigente")) -> Vigente | O3: =INDEX(Locais!$B$2:$B$13,MATCH(H3,Locais!$A$2:$A$13,0)) -> Regional - Fortaleza | P3: =INDEX(Locais!$C$2:$C$13,MATCH(H3,Locais!$A$2:$A$13,0)) -> Nordeste
A4: ATV-00003 | B4: Desktop | C4: Dell | D4: OptiPlex 7090 | E4: 43749 | F4: 44844 | G4: Em Uso | H4: LOC-05 | I4: Operações | J4: N | K4: 5711.21 | L4: =IF(E4="","",ROUND((Indicadores!$B$4-E4)/365.25,1)) -> 7 | M4: =IF(E4="","Virtual",IF(L4>=Indicadores!$B$6,"Fim de Vida",IF(L4>=Indicadores!$B$5,"Envelhecendo","Atual"))) -> Fim de Vida | N4: =IF(F4="","N/A",IF(F4<Indicadores!$B$4,"Vencida","Vigente")) -> Vencida | O4: =INDEX(Locais!$B$2:$B$13,MATCH(H4,Locais!$A$2:$A$13,0)) -> Regional - Porto Alegre | P4: =INDEX(Locais!$C$2:$C$13,MATCH(H4,Locais!$A$2:$A$13,0)) -> Sul
A5: ATV-00004 | B5: Desktop | C5: Dell | D5: OptiPlex 7090 | E5: 45130 | F5: 46225 | G5: Em Uso | H5: LOC-01 | I5: Riscos | J5: N | K5: 4768.17 | L5: =IF(E5="","",ROUND((Indicadores!$B$4-E5)/365.25,1)) -> 3.2 | M5: =IF(E5="","Virtual",IF(L5>=Indicadores!$B$6,"Fim de Vida",IF(L5>=Indicadores!$B$5,"Envelhecendo","Atual"))) -> Envelhecendo | N5: =IF(F5="","N/A",IF(F5<Indicadores!$B$4,"Vencida","Vigente")) -> Vencida | O5: =INDEX(Locais!$B$2:$B$13,MATCH(H5,Locais!$A$2:$A$13,0)) -> Sede - Brasília | P5: =INDEX(Locais!$C$2:$C$13,MATCH(H5,Locais!$A$2:$A$13,0)) -> Centro-Oeste
A6: ATV-00005 | B6: Notebook | C6: Lenovo | D6: ThinkPad T14 | E6: 45352 | F6: 46447 | G6: Em Estoque | H6: LOC-04 | I6: Jurídico | J6: N | K6: 7655.15 | L6: =IF(E6="","",ROUND((Indicadores!$B$4-E6)/365.25,1)) -> 2.6 | M6: =IF(E6="","Virtual",IF(L6>=Indicadores!$B$6,"Fim de Vida",IF(L6>=Indicadores!$B$5,"Envelhecendo","Atual"))) -> Atual | N6: =IF(F6="","N/A",IF(F6<Indicadores!$B$4,"Vencida","Vigente")) -> Vigente | O6: =INDEX(Locais!$B$2:$B$13,MATCH(H6,Locais!$A$2:$A$13,0)) -> Regional - Belo Horizonte | P6: =INDEX(Locais!$C$2:$C$13,MATCH(H6,Locais!$A$2:$A$13,0)) -> Sudeste
A7: ATV-00006 | B7: Notebook | C7: Dell | D7: Latitude 5440 | E7: 43292 | F7: 44387 | G7: Baixado | H7: LOC-02 | I7: Comunicação | J7: N | K7: 7890.22 | L7: =IF(E7="","",ROUND((Indicadores!$B$4-E7)/365.25,1)) -> 8.3 | M7: =IF(E7="","Virtual",IF(L7>=Indicadores!$B$6,"Fim de Vida",IF(L7>=Indicadores!$B$5,"Envelhecendo","Atual"))) -> Fim de Vida | N7: =IF(F7="","N/A",IF(F7<Indicadores!$B$4,"Vencida","Vigente")) -> Vencida | O7: =INDEX(Locais!$B$2:$B$13,MATCH(H7,Locais!$A$2:$A$13,0)) -> Regional - São Paulo | P7: =INDEX(Locais!$C$2:$C$13,MATCH(H7,Locais!$A$2:$A$13,0)) -> Sudeste
A8: ATV-00007 | B8: Workstation | C8: Dell | D8: Precision 3660 | E8: 45435 | F8: 47260 | G8: Em Manutenção | H8: LOC-12 | I8: Administração | J8: N | K8: 17919.54 | L8: =IF(E8="","",ROUND((Indicadores!$B$4-E8)/365.25,1)) -> 2.4 | M8: =IF(E8="","Virtual",IF(L8>=Indicadores!$B$6,"Fim de Vida",IF(L8>=Indicadores!$B$5,"Envelhecendo","Atual"))) -> Atual | N8: =IF(F8="","N/A",IF(F8<Indicadores!$B$4,"Vencida","Vigente")) -> Vigente | O8: =INDEX(Locais!$B$2:$B$13,MATCH(H8,Locais!$A$2:$A$13,0)) -> Regional - Goiânia | P8: =INDEX(Locais!$C$2:$C$13,MATCH(H8,Locais!$A$2:$A$13,0)) -> Centro-Oeste
A9: ATV-00008 | B9: Desktop | C9: HP | D9: EliteDesk 800 G6 | E9: 45637 | F9: 46732 | G9: Em Uso | H9: LOC-08 | I9: Administração | J9: N | K9: 5970.66 | L9: =IF(E9="","",ROUND((Indicadores!$B$4-E9)/365.25,1)) -> 1.9 | M9: =IF(E9="","Virtual",IF(L9>=Indicadores!$B$6,"Fim de Vida",IF(L9>=Indicadores!$B$5,"Envelhecendo","Atual"))) -> Atual | N9: =IF(F9="","N/A",IF(F9<Indicadores!$B$4,"Vencida","Vigente")) -> Vigente | O9: =INDEX(Locais!$B$2:$B$13,MATCH(H9,Locais!$A$2:$A$13,0)) -> Regional - Recife | P9: =INDEX(Locais!$C$2:$C$13,MATCH(H9,Locais!$A$2:$A$13,0)) -> Nordeste
A10: ATV-00009 | B10: Desktop | C10: Lenovo | D10: ThinkCentre M70q | E10: 45367 | F10: 46462 | G10: Em Manutenção | H10: LOC-05 | I10: Compras | J10: N | K10: 5550.46 | L10: =IF(E10="","",ROUND((Indicadores!$B$4-E10)/365.25,1)) -> 2.6 | M10: =IF(E10="","Virtual",IF(L10>=Indicadores!$B$6,"Fim de Vida",IF(L10>=Indicadores!$B$5,"Envelhecendo","Atual"))) -> Atual | N10: =IF(F10="","N/A",IF(F10<Indicadores!$B$4,"Vencida","Vigente")) -> Vigente | O10: =INDEX(Locais!$B$2:$B$13,MATCH(H10,Locais!$A$2:$A$13,0)) -> Regional - Porto Alegre | P10: =INDEX(Locais!$C$2:$C$13,MATCH(H10,Locais!$A$2:$A$13,0)) -> Sul
A11: ATV-00010 | B11: Desktop | C11: Dell | D11: OptiPlex 7010 | E11: 44973 | F11: 46068 | G11: Em Estoque | H11: LOC-01 | I11: TI | J11: N | K11: 5537.41 | L11: =IF(E11="","",ROUND((Indicadores!$B$4-E11)/365.25,1)) -> 3.7 | M11: =IF(E11="","Virtual",IF(L11>=Indicadores!$B$6,"Fim de Vida",IF(L11>=Indicadores!$B$5,"Envelhecendo","Atual"))) -> Envelhecendo | N11: =IF(F11="","N/A",IF(F11<Indicadores!$B$4,"Vencida","Vigente")) -> Vencida | O11: =INDEX(Locais!$B$2:$B$13,MATCH(H11,Locais!$A$2:$A$13,0)) -> Sede - Brasília | P11: =INDEX(Locais!$C$2:$C$13,MATCH(H11,Locais!$A$2:$A$13,0)) -> Centro-Oeste
A12: ATV-00011 | B12: Desktop | C12: Lenovo | D12: ThinkCentre M70q | E12: 46005 | F12: 47100 | G12: Pool - Disponível | H12: LOC-08 | I12: Finanças | J12: S | K12: 4879.7 | L12: =IF(E12="","",ROUND((Indicadores!$B$4-E12)/365.25,1)) -> 0.8 | M12: =IF(E12="","Virtual",IF(L12>=Indicadores!$B$6,"Fim de Vida",IF(L12>=Indicadores!$B$5,"Envelhecendo","Atual"))) -> Atual | N12: =IF(F12="","N/A",IF(F12<Indicadores!$B$4,"Vencida","Vigente")) -> Vigente | O12: =INDEX(Locais!$B$2:$B$13,MATCH(H12,Locais!$A$2:$A$13,0)) -> Regional - Recife | P12: =INDEX(Locais!$C$2:$C$13,MATCH(H12,Locais!$A$2:$A$13,0)) -> Nordeste
A13: ATV-00012 | B13: Notebook | C13: Lenovo | D13: ThinkPad T14 | E13: 44692 | F13: 45787 | G13: Em Estoque | H13: LOC-03 | I13: Comunicação | J13: N | K13: 8177.68 | L13: =IF(E13="","",ROUND((Indicadores!$B$4-E13)/365.25,1)) -> 4.4 | M13: =IF(E13="","Virtual",IF(L13>=Indicadores!$B$6,"Fim de Vida",IF(L13>=Indicadores!$B$5,"Envelhecendo","Atual"))) -> Envelhecendo | N13: =IF(F13="","N/A",IF(F13<Indicadores!$B$4,"Vencida","Vigente")) -> Vencida | O13: =INDEX(Locais!$B$2:$B$13,MATCH(H13,Locais!$A$2:$A$13,0)) -> Regional - Rio de Janeiro | P13: =INDEX(Locais!$C$2:$C$13,MATCH(H13,Locais!$A$2:$A$13,0)) -> Sudeste
... A4801: ATV-04800 | B4801: Desktop | C4801: Dell | D4801: OptiPlex 7010 | E4801: 45987 | F4801: 47082 | G4801: Em Uso | H4801: LOC-08 | I4801: Compras | J4801: N | K4801: 6359.98 | L4801: =IF(E4801="","",ROUND((Indicadores!$B$4-E4801)/365.25,1)) -> 0.9 | M4801: =IF(E4801="","Virtual",IF(L4801>=Indicadores!$B$6,"Fim de Vida",IF(L4801>=Indicadores!$B$5,"Envelhecendo","Atual"))) -> Atual | N4801: =IF(F4801="","N/A",IF(F4801<Indicadores!$B$4,"Vencida","Vigente")) -> Vigente | O4801: =INDEX(Locais!$B$2:$B$13,MATCH(H4801,Locais!$A$2:$A$13,0)) -> Regional - Recife | P4801: =INDEX(Locais!$C$2:$C$13,MATCH(H4801,Locais!$A$2:$A$13,0)) -> Nordeste
A4802: ATV-04801 | B4802: Máquina Virtual | C4802: Virtual | D4802: VM-Padrão | G4802: Pool - Disponível | H4802: LOC-01 | I4802: TI | J4802: S | K4802: 0 | L4802: =IF(E4802="","",ROUND((Indicadores!$B$4-E4802)/365.25,1)) | M4802: =IF(E4802="","Virtual",IF(L4802>=Indicadores!$B$6,"Fim de Vida",IF(L4802>=Indicadores!$B$5,"Envelhecendo","Atual"))) -> Virtual | N4802: =IF(F4802="","N/A",IF(F4802<Indicadores!$B$4,"Vencida","Vigente")) -> N/A | O4802: =INDEX(Locais!$B$2:$B$13,MATCH(H4802,Locais!$A$2:$A$13,0)) -> Sede - Brasília | P4802: =INDEX(Locais!$C$2:$C$13,MATCH(H4802,Locais!$A$2:$A$13,0)) -> Centro-Oeste
A4803: ATV-04802 | B4803: Máquina Virtual | C4803: Virtual | D4803: VM-Padrão | G4803: Pool - Disponível | H4803: LOC-01 | I4803: TI | J4803: S | K4803: 0 | L4803: =IF(E4803="","",ROUND((Indicadores!$B$4-E4803)/365.25,1)) | M4803: =IF(E4803="","Virtual",IF(L4803>=Indicadores!$B$6,"Fim de Vida",IF(L4803>=Indicadores!$B$5,"Envelhecendo","Atual"))) -> Virtual | N4803: =IF(F4803="","N/A",IF(F4803<Indicadores!$B$4,"Vencida","Vigente")) -> N/A | O4803: =INDEX(Locais!$B$2:$B$13,MATCH(H4803,Locais!$A$2:$A$13,0)) -> Sede - Brasília | P4803: =INDEX(Locais!$C$2:$C$13,MATCH(H4803,Locais!$A$2:$A$13,0)) -> Centro-Oeste
A4804: ATV-04803 | B4804: Máquina Virtual | C4804: Virtual | D4804: VM-Padrão | G4804: Pool - Disponível | H4804: LOC-01 | I4804: TI | J4804: S | K4804: 0 | L4804: =IF(E4804="","",ROUND((Indicadores!$B$4-E4804)/365.25,1)) | M4804: =IF(E4804="","Virtual",IF(L4804>=Indicadores!$B$6,"Fim de Vida",IF(L4804>=Indicadores!$B$5,"Envelhecendo","Atual"))) -> Virtual | N4804: =IF(F4804="","N/A",IF(F4804<Indicadores!$B$4,"Vencida","Vigente")) -> N/A | O4804: =INDEX(Locais!$B$2:$B$13,MATCH(H4804,Locais!$A$2:$A$13,0)) -> Sede - Brasília | P4804: =INDEX(Locais!$C$2:$C$13,MATCH(H4804,Locais!$A$2:$A$13,0)) -> Centro-Oeste
A4805: ATV-04804 | B4805: Máquina Virtual | C4805: Virtual | D4805: VM-Padrão | G4805: Pool - Disponível | H4805: LOC-01 | I4805: TI | J4805: S | K4805: 0 | L4805: =IF(E4805="","",ROUND((Indicadores!$B$4-E4805)/365.25,1)) | M4805: =IF(E4805="","Virtual",IF(L4805>=Indicadores!$B$6,"Fim de Vida",IF(L4805>=Indicadores!$B$5,"Envelhecendo","Atual"))) -> Virtual | N4805: =IF(F4805="","N/A",IF(F4805<Indicadores!$B$4,"Vencida","Vigente")) -> N/A | O4805: =INDEX(Locais!$B$2:$B$13,MATCH(H4805,Locais!$A$2:$A$13,0)) -> Sede - Brasília | P4805: =INDEX(Locais!$C$2:$C$13,MATCH(H4805,Locais!$A$2:$A$13,0)) -> Centro-Oeste
A4806: ATV-04805 | B4806: Máquina Virtual | C4806: Virtual | D4806: VM-Desempenho | G4806: Pool - Disponível | H4806: LOC-01 | I4806: TI | J4806: S | K4806: 0 | L4806: =IF(E4806="","",ROUND((Indicadores!$B$4-E4806)/365.25,1)) | M4806: =IF(E4806="","Virtual",IF(L4806>=Indicadores!$B$6,"Fim de Vida",IF(L4806>=Indicadores!$B$5,"Envelhecendo","Atual"))) -> Virtual | N4806: =IF(F4806="","N/A",IF(F4806<Indicadores!$B$4,"Vencida","Vigente")) -> N/A | O4806: =INDEX(Locais!$B$2:$B$13,MATCH(H4806,Locais!$A$2:$A$13,0)) -> Sede - Brasília | P4806: =INDEX(Locais!$C$2:$C$13,MATCH(H4806,Locais!$A$2:$A$13,0)) -> Centro-Oeste
A4807: ATV-04806 | B4807: Máquina Virtual | C4807: Virtual | D4807: VM-Desempenho | G4807: Pool - Emprestado | H4807: LOC-01 | I4807: TI | J4807: S | K4807: 0 | L4807: =IF(E4807="","",ROUND((Indicadores!$B$4-E4807)/365.25,1)) | M4807: =IF(E4807="","Virtual",IF(L4807>=Indicadores!$B$6,"Fim de Vida",IF(L4807>=Indicadores!$B$5,"Envelhecendo","Atual"))) -> Virtual | N4807: =IF(F4807="","N/A",IF(F4807<Indicadores!$B$4,"Vencida","Vigente")) -> N/A | O4807: =INDEX(Locais!$B$2:$B$13,MATCH(H4807,Locais!$A$2:$A$13,0)) -> Sede - Brasília | P4807: =INDEX(Locais!$C$2:$C$13,MATCH(H4807,Locais!$A$2:$A$13,0)) -> Centro-Oeste
A4808: ATV-04807 | B4808: Máquina Virtual | C4808: Virtual | D4808: VM-Padrão | G4808: Pool - Disponível | H4808: LOC-01 | I4808: TI | J4808: S | K4808: 0 | L4808: =IF(E4808="","",ROUND((Indicadores!$B$4-E4808)/365.25,1)) | M4808: =IF(E4808="","Virtual",IF(L4808>=Indicadores!$B$6,"Fim de Vida",IF(L4808>=Indicadores!$B$5,"Envelhecendo","Atual"))) -> Virtual | N4808: =IF(F4808="","N/A",IF(F4808<Indicadores!$B$4,"Vencida","Vigente")) -> N/A | O4808: =INDEX(Locais!$B$2:$B$13,MATCH(H4808,Locais!$A$2:$A$13,0)) -> Sede - Brasília | P4808: =INDEX(Locais!$C$2:$C$13,MATCH(H4808,Locais!$A$2:$A$13,0)) -> Centro-Oeste
A4809: ATV-04808 | B4809: Máquina Virtual | C4809: Virtual | D4809: VM-Padrão | G4809: Pool - Emprestado | H4809: LOC-01 | I4809: TI | J4809: S | K4809: 0 | L4809: =IF(E4809="","",ROUND((Indicadores!$B$4-E4809)/365.25,1)) | M4809: =IF(E4809="","Virtual",IF(L4809>=Indicadores!$B$6,"Fim de Vida",IF(L4809>=Indicadores!$B$5,"Envelhecendo","Atual"))) -> Virtual | N4809: =IF(F4809="","N/A",IF(F4809<Indicadores!$B$4,"Vencida","Vigente")) -> N/A | O4809: =INDEX(Locais!$B$2:$B$13,MATCH(H4809,Locais!$A$2:$A$13,0)) -> Sede - Brasília | P4809: =INDEX(Locais!$C$2:$C$13,MATCH(H4809,Locais!$A$2:$A$13,0)) -> Centro-Oeste
A4810: ATV-04809 | B4810: Máquina Virtual | C4810: Virtual | D4810: VM-Padrão | G4810: Pool - Disponível | H4810: LOC-01 | I4810: TI | J4810: S | K4810: 0 | L4810: =IF(E4810="","",ROUND((Indicadores!$B$4-E4810)/365.25,1)) | M4810: =IF(E4810="","Virtual",IF(L4810>=Indicadores!$B$6,"Fim de Vida",IF(L4810>=Indicadores!$B$5,"Envelhecendo","Atual"))) -> Virtual | N4810: =IF(F4810="","N/A",IF(F4810<Indicadores!$B$4,"Vencida","Vigente")) -> N/A | O4810: =INDEX(Locais!$B$2:$B$13,MATCH(H4810,Locais!$A$2:$A$13,0)) -> Sede - Brasília | P4810: =INDEX(Locais!$C$2:$C$13,MATCH(H4810,Locais!$A$2:$A$13,0)) -> Centro-Oeste
A4811: ATV-04810 | B4811: Máquina Virtual | C4811: Virtual | D4811: VM-Padrão | G4811: Pool - Disponível | H4811: LOC-01 | I4811: TI | J4811: S | K4811: 0 | L4811: =IF(E4811="","",ROUND((Indicadores!$B$4-E4811)/365.25,1)) | M4811: =IF(E4811="","Virtual",IF(L4811>=Indicadores!$B$6,"Fim de Vida",IF(L4811>=Indicadores!$B$5,"Envelhecendo","Atual"))) -> Virtual | N4811: =IF(F4811="","N/A",IF(F4811<Indicadores!$B$4,"Vencida","Vigente")) -> N/A | O4811: =INDEX(Locais!$B$2:$B$13,MATCH(H4811,Locais!$A$2:$A$13,0)) -> Sede - Brasília | P4811: =INDEX(Locais!$C$2:$C$13,MATCH(H4811,Locais!$A$2:$A$13,0)) -> Centro-Oeste
A4812: ATV-04811 | B4812: Máquina Virtual | C4812: Virtual | D4812: VM-Desempenho | G4812: Pool - Disponível | H4812: LOC-01 | I4812: TI | J4812: S | K4812: 0 | L4812: =IF(E4812="","",ROUND((Indicadores!$B$4-E4812)/365.25,1)) | M4812: =IF(E4812="","Virtual",IF(L4812>=Indicadores!$B$6,"Fim de Vida",IF(L4812>=Indicadores!$B$5,"Envelhecendo","Atual"))) -> Virtual | N4812: =IF(F4812="","N/A",IF(F4812<Indicadores!$B$4,"Vencida","Vigente")) -> N/A | O4812: =INDEX(Locais!$B$2:$B$13,MATCH(H4812,Locais!$A$2:$A$13,0)) -> Sede - Brasília | P4812: =INDEX(Locais!$C$2:$C$13,MATCH(H4812,Locais!$A$2:$A$13,0)) -> Centro-Oeste
A4813: ATV-04812 | B4813: Máquina Virtual | C4813: Virtual | D4813: VM-Padrão | G4813: Pool - Disponível | H4813: LOC-01 | I4813: TI | J4813: S | K4813: 0 | L4813: =IF(E4813="","",ROUND((Indicadores!$B$4-E4813)/365.25,1)) | M4813: =IF(E4813="","Virtual",IF(L4813>=Indicadores!$B$6,"Fim de Vida",IF(L4813>=Indicadores!$B$5,"Envelhecendo","Atual"))) -> Virtual | N4813: =IF(F4813="","N/A",IF(F4813<Indicadores!$B$4,"Vencida","Vigente")) -> N/A | O4813: =INDEX(Locais!$B$2:$B$13,MATCH(H4813,Locais!$A$2:$A$13,0)) -> Sede - Brasília | P4813: =INDEX(Locais!$C$2:$C$13,MATCH(H4813,Locais!$A$2:$A$13,0)) -> Centro-Oeste
... A5001: ATV-05000 | B5001: Máquina Virtual | C5001: Virtual | D5001: VM-Desempenho | G5001: Pool - Disponível | H5001: LOC-01 | I5001: TI | J5001: S | K5001: 0 | L5001: =IF(E5001="","",ROUND((Indicadores!$B$4-E5001)/365.25,1)) | M5001: =IF(E5001="","Virtual",IF(L5001>=Indicadores!$B$6,"Fim de Vida",IF(L5001>=Indicadores!$B$5,"Envelhecendo","Atual"))) -> Virtual | N5001: =IF(F5001="","N/A",IF(F5001<Indicadores!$B$4,"Vencida","Vigente")) -> N/A | O5001: =INDEX(Locais!$B$2:$B$13,MATCH(H5001,Locais!$A$2:$A$13,0)) -> Sede - Brasília | P5001: =INDEX(Locais!$C$2:$C$13,MATCH(H5001,Locais!$A$2:$A$13,0)) -> Centro-Oeste

Sheet Locais
A1: id_local | B1: nome_local | C1: regiao
A2: LOC-01 | B2: Sede - Brasília | C2: Centro-Oeste
A3: LOC-02 | B3: Regional - São Paulo | C3: Sudeste
A4: LOC-03 | B4: Regional - Rio de Janeiro | C4: Sudeste
A5: LOC-04 | B5: Regional - Belo Horizonte | C5: Sudeste
A6: LOC-05 | B6: Regional - Porto Alegre | C6: Sul
A7: LOC-06 | B7: Regional - Curitiba | C7: Sul
A8: LOC-07 | B8: Regional - Salvador | C8: Nordeste
A9: LOC-08 | B9: Regional - Recife | C9: Nordeste
A10: LOC-09 | B10: Regional - Fortaleza | C10: Nordeste
A11: LOC-10 | B11: Regional - Belém | C11: Norte
A12: LOC-11 | B12: Regional - Manaus | C12: Norte
A13: LOC-12 | B13: Regional - Goiânia | C13: Centro-Oeste

Sheet Movimentações
A1: id_movimentacao | B1: id_ativo | C1: tipo_movimentacao | D1: data_movimentacao | E1: id_local_origem | F1: id_local_destino | G1: departamento_solicitante
A2: MOV-000001 | B2: ATV-02671 | C2: Despacho | D2: 45857 | E2: LOC-01 | F2: LOC-02 | G2: Finanças
A3: MOV-000002 | B3: ATV-02689 | C3: Transferência | D3: 45679 | E3: LOC-04 | F3: LOC-08 | G3: Operações
A4: MOV-000003 | B4: ATV-02928 | C4: Devolução | D4: 45924 | E4: LOC-02 | F4: LOC-01 | G4: TI
A5: MOV-000004 | B5: ATV-00698 | C5: Transferência | D5: 46048 | E5: LOC-09 | F5: LOC-06 | G5: Comunicação
A6: MOV-000005 | B6: ATV-02722 | C6: Devolução | D6: 45656 | E6: LOC-12 | F6: LOC-01 | G6: Administração
A7: MOV-000006 | B7: ATV-02025 | C7: Devolução ao Pool | D7: 46104 | E7: LOC-02 | F7: LOC-01 | G7: Compras
A8: MOV-000007 | B8: ATV-01211 | C8: Despacho | D8: 45964 | E8: LOC-01 | F8: LOC-08 | G8: Comunicação
A9: MOV-000008 | B9: ATV-04211 | C9: Transferência | D9: 45353 | E9: LOC-12 | F9: LOC-02 | G9: Compras
A10: MOV-000009 | B10: ATV-04853 | C10: Devolução ao Pool | D10: 45870 | E10: LOC-01 | F10: LOC-01 | G10: TI
A11: MOV-000010 | B11: ATV-00663 | C11: Despacho | D11: 45853 | E11: LOC-01 | F11: LOC-01 | G11: Finanças
A12: MOV-000011 | B12: ATV-01786 | C12: Transferência | D12: 45870 | E12: LOC-01 | F12: LOC-08 | G12: Compras
A13: MOV-000012 | B13: ATV-03472 | C13: Despacho | D13: 45550 | E13: LOC-01 | F13: LOC-01 | G13: Jurídico
... A12001: MOV-012000 | B12001: ATV-02062 | C12001: Transferência | D12001: 45846 | E12001: LOC-09 | F12001: LOC-02 | G12001: Finanças

Sheet Incidentes
A1: id_incidente | B1: id_ativo | C1: id_local | D1: categoria | E1: gravidade | F1: data_abertura | G1: data_resolucao | H1: horas_resolucao
A2: INC-000001 | B2: ATV-00946 | C2: LOC-12 | D2: Hardware | E2: Baixa | F2: 46263 | G2: 46265 | H2: 49.6
A3: INC-000002 | B3: ATV-04300 | C3: LOC-01 | D3: Software | E3: Baixa | F3: 46181 | G3: 46181 | H3: 8.1
A4: INC-000003 | B4: ATV-01961 | C4: LOC-08 | D4: Rede | E4: Baixa | F4: 46084 | G4: 46085 | H4: 24.1
A5: INC-000004 | B5: ATV-00355 | C5: LOC-01 | D5: Desempenho | E5: Baixa | F5: 46091 | G5: 46091 | H5: 9.5
A6: INC-000005 | B6: ATV-00531 | C6: LOC-01 | D6: Acesso | E6: Baixa | F6: 46091 | G6: 46091 | H6: 14.1
A7: INC-000006 | B7: ATV-04400 | C7: LOC-01 | D7: Hardware | E7: Baixa | F7: 46184 | G7: 46184 | H7: 16.2
A8: INC-000007 | B8: ATV-01527 | C8: LOC-07 | D8: Software | E8: Média | F8: 46021 | G8: 46021 | H8: 3
A9: INC-000008 | B9: ATV-01684 | C9: LOC-05 | D9: Hardware | E9: Baixa | F9: 46040 | G9: 46040 | H9: 13.4
A10: INC-000009 | B10: ATV-03314 | C10: LOC-12 | D10: Software | E10: Média | F10: 46031 | G10: 46031 | H10: 5.9
A11: INC-000010 | B11: ATV-00061 | C11: LOC-09 | D11: Hardware | E11: Crítica | F11: 46013 | G11: 46013 | H11: 2.7
A12: INC-000011 | B12: ATV-00436 | C12: LOC-05 | D12: Acesso | E12: Alta | F12: 46081 | G12: 46081 | H12: 4.5
A13: INC-000012 | B13: ATV-03928 | C13: LOC-01 | D13: Acesso | E13: Baixa | F13: 46004 | G13: 46005 | H13: 37.2
... A9001: INC-009000 | B9001: ATV-00340 | C9001: LOC-01 | D9001: Software | E9001: Alta | F9001: 46132 | G9001: 46132 | H9001: 2.9
